<mujoco>
  <asset>
    <texture name="grid" type="2d" builtin="checker" rgb1=".1 .2 .3"
     rgb2=".2 .3 .4" width="300" height="300" mark="none"/>
    <material name="grid" texture="grid" texrepeat="1 1"
     texuniform="true" reflectance=".2"/>
  </asset>

  <worldbody>
    <light name="light" pos="0 0 1"/>
    <geom name="floor" type="plane" pos="0 0 -.5" size="2 2 .1" material="grid"/>
    <camera name="fixed" pos="0 -1.3 .5" xyaxes="1 0 0 0 1 2"/>
    <body name="box" pos=".2 .2 .1">
      <joint name="rotate_x" pos="0 0 0" axis="1 0 0" range="-.25 .25" damping="20" />
      <joint name="rotate_y" pos="0 0 0" axis="0 1 0" range="-.25 .25" damping="20" />
      <geom name="box" type="box" size=".2 .2 .02" rgba="1 0 0 1"/>
    </body>
    <body name="ball" pos=".2 .2 .4">
      <freejoint name="ball"/>
      <geom name="ball" pos="0 0 0" size=".05" rgba="0 1 0 1"/>
    </body>

  </worldbody>

  <actuator>
    <general name="act_x" joint="rotate_x" ctrlrange="-1 1" gainprm="1000 0 0" />
    <general name="act_y" joint="rotate_y" ctrlrange="-1 1" gainprm="1000 0 0" />
  </actuator>
</mujoco>